2022-08-13 14:32:20.290 | ERROR    | module:require_module:99 - HubService 未启用
2022-08-13 14:32:20.298 | INFO     | graia.saya:require:134 - module loading finished: module.Nudge
2022-08-13 14:32:20.628 | INFO     | graia.saya:require:134 - module loading finished: module.anyvoice
2022-08-13 14:32:20.649 | INFO     | graia.saya:require:134 - module loading finished: module.groupmanager
2022-08-13 14:32:20.818 | ERROR    | module:require_module:99 - 'gbk' codec can't decode byte 0x9c in position 10: illegal multibyte sequence
2022-08-13 14:32:20.825 | INFO     | graia.saya:require:134 - module loading finished: module.logger
2022-08-13 14:32:20.843 | INFO     | graia.saya:require:134 - module loading finished: module.manager
2022-08-13 14:32:20.849 | ERROR    | graia.ariadne.util:loguru_exc_callback:101 - Exception:
Traceback (most recent call last):

  File "C:\Users\Administrator\Desktop\god-loong-bot-project\module\__init__.py", line 87, in require_module
    saya.require(module.pack)
    │    │       │      └ 'module.petpeter'
    │    │       └ Module(petpeter)
    │    │         	pack: module.petpeter
    │    │         	version: Unknown
    │    │         	author: ['Unknown']
    │    │         	pypi: False
    │    │         	category: miscellaneous
    │    │         	descrip...
    │    └ <function Saya.require at 0x00000274A0F7C550>
    └ <graia.saya.Saya object at 0x00000274A1A86650>

  File "C:\Users\Administrator\Desktop\god-loong-bot-project\.venv\lib\site-packages\graia\saya\__init__.py", line 120, in require
    channel = self.require_resolve(module)
              │    │               └ 'module.petpeter'
              │    └ <function Saya.require_resolve at 0x00000274A0F7C430>
              └ <graia.saya.Saya object at 0x00000274A1A86650>

  File "C:\Users\Administrator\Desktop\god-loong-bot-project\.venv\lib\site-packages\graia\saya\__init__.py", line 76, in require_resolve
    imported_module = importlib.import_module(module, module)
                      │         │             │       └ 'module.petpeter'
                      │         │             └ 'module.petpeter'
                      │         └ <function import_module at 0x000002749E814280>
                      └ <module 'importlib' from 'D:\\Python310\\lib\\importlib\\__init__.py'>

  File "D:\Python310\lib\importlib\__init__.py", line 126, in import_module
    return _bootstrap._gcd_import(name[level:], package, level)
           │          │           │    │        │        └ 0
           │          │           │    │        └ 'module.petpeter'
           │          │           │    └ 0
           │          │           └ 'module.petpeter'
           │          └ <function _gcd_import at 0x000002749E6C3490>
           └ <module '_frozen_importlib' (frozen)>

  File "<frozen importlib._bootstrap>", line 1050, in _gcd_import
  File "<frozen importlib._bootstrap>", line 1027, in _find_and_load
  File "<frozen importlib._bootstrap>", line 1006, in _find_and_load_unlocked
  File "<frozen importlib._bootstrap>", line 688, in _load_unlocked
  File "<frozen importlib._bootstrap_external>", line 883, in exec_module
  File "<frozen importlib._bootstrap>", line 241, in _call_with_frames_removed

  File "C:\Users\Administrator\Desktop\god-loong-bot-project\module\petpeter\__init__.py", line 30, in <module>
    BOT = bot()
          └ <class 'library.Bot.bot'>

  File "C:\Users\Administrator\Desktop\god-loong-bot-project\library\Bot.py", line 6, in __init__
    self.weijingci = json.loads(f.read())
    │                │    │     │ └ <method 'read' of '_io.TextIOWrapper' objects>
    │                │    │     └ <_io.TextIOWrapper name='C:\\Users\\Administrator\\Desktop\\god-loong-bot-project/library/weijinci.txt' mode='r' encoding='cp...
    │                │    └ <function loads at 0x00000274A0A8A8C0>
    │                └ <module 'json' from 'D:\\Python310\\lib\\json\\__init__.py'>
    └ <library.Bot.bot object at 0x00000274D25BE620>

UnicodeDecodeError: 'gbk' codec can't decode byte 0x9c in position 10: illegal multibyte sequence


During handling of the above exception, another exception occurred:


Traceback (most recent call last):

> File "C:\Users\Administrator\Desktop\god-loong-bot-project\main.py", line 33, in <module>
    modules.require_modules(saya, log_exception=False)
    │       │               └ <graia.saya.Saya object at 0x00000274A1A86650>
    │       └ <function Modules.require_modules at 0x00000274A2DE48B0>
    └ Modules(12)
      Module(中心服务)
      	pack: module.hub_service
      	version: 0.1b
      	author: ['nullqwertyuiop']
      	pypi: False
      	category: utility...

  File "C:\Users\Administrator\Desktop\god-loong-bot-project\module\__init__.py", line 71, in require_modules
    self.require_module(module, saya, log_exception)
    │    │              │       │     └ False
    │    │              │       └ <graia.saya.Saya object at 0x00000274A1A86650>
    │    │              └ Module(petpeter)
    │    │                	pack: module.petpeter
    │    │                	version: Unknown
    │    │                	author: ['Unknown']
    │    │                	pypi: False
    │    │                	category: miscellaneous
    │    │                	descrip...
    │    └ <function Modules.require_module at 0x00000274A2DE4940>
    └ Modules(12)
      Module(中心服务)
      	pack: module.hub_service
      	version: 0.1b
      	author: ['nullqwertyuiop']
      	pypi: False
      	category: utility...

  File "C:\Users\Administrator\Desktop\god-loong-bot-project\module\__init__.py", line 99, in require_module
    logger.error(e)
    └ <module 'module.logger' from 'C:\\Users\\Administrator\\Desktop\\god-loong-bot-project\\module\\logger\\__init__.py'>

AttributeError: module 'module.logger' has no attribute 'error'
2022-08-13 14:32:42.466 | ERROR    | module:require_module:99 - HubService 未启用
2022-08-13 14:32:42.471 | INFO     | graia.saya:require:134 - module loading finished: module.Nudge
2022-08-13 14:32:42.763 | INFO     | graia.saya:require:134 - module loading finished: module.anyvoice
2022-08-13 14:32:42.783 | INFO     | graia.saya:require:134 - module loading finished: module.groupmanager
2022-08-13 14:32:42.948 | ERROR    | module:require_module:99 - 'gbk' codec can't decode byte 0x9c in position 10: illegal multibyte sequence
2022-08-13 14:32:42.953 | INFO     | graia.saya:require:134 - module loading finished: module.logger
2022-08-13 14:32:42.969 | INFO     | graia.saya:require:134 - module loading finished: module.manager
2022-08-13 14:32:42.973 | ERROR    | graia.ariadne.util:loguru_exc_callback:101 - Exception:
Traceback (most recent call last):

  File "C:\Users\Administrator\Desktop\god-loong-bot-project\module\__init__.py", line 87, in require_module
    saya.require(module.pack)
    │    │       │      └ 'module.petpeter'
    │    │       └ Module(petpeter)
    │    │         	pack: module.petpeter
    │    │         	version: Unknown
    │    │         	author: ['Unknown']
    │    │         	pypi: False
    │    │         	category: miscellaneous
    │    │         	descrip...
    │    └ <function Saya.require at 0x00000205AE17C550>
    └ <graia.saya.Saya object at 0x00000205AEC8A5F0>

  File "C:\Users\Administrator\Desktop\god-loong-bot-project\.venv\lib\site-packages\graia\saya\__init__.py", line 120, in require
    channel = self.require_resolve(module)
              │    │               └ 'module.petpeter'
              │    └ <function Saya.require_resolve at 0x00000205AE17C430>
              └ <graia.saya.Saya object at 0x00000205AEC8A5F0>

  File "C:\Users\Administrator\Desktop\god-loong-bot-project\.venv\lib\site-packages\graia\saya\__init__.py", line 76, in require_resolve
    imported_module = importlib.import_module(module, module)
                      │         │             │       └ 'module.petpeter'
                      │         │             └ 'module.petpeter'
                      │         └ <function import_module at 0x00000205ABA44280>
                      └ <module 'importlib' from 'D:\\Python310\\lib\\importlib\\__init__.py'>

  File "D:\Python310\lib\importlib\__init__.py", line 126, in import_module
    return _bootstrap._gcd_import(name[level:], package, level)
           │          │           │    │        │        └ 0
           │          │           │    │        └ 'module.petpeter'
           │          │           │    └ 0
           │          │           └ 'module.petpeter'
           │          └ <function _gcd_import at 0x00000205AB8F3490>
           └ <module '_frozen_importlib' (frozen)>

  File "<frozen importlib._bootstrap>", line 1050, in _gcd_import
  File "<frozen importlib._bootstrap>", line 1027, in _find_and_load
  File "<frozen importlib._bootstrap>", line 1006, in _find_and_load_unlocked
  File "<frozen importlib._bootstrap>", line 688, in _load_unlocked
  File "<frozen importlib._bootstrap_external>", line 883, in exec_module
  File "<frozen importlib._bootstrap>", line 241, in _call_with_frames_removed

  File "C:\Users\Administrator\Desktop\god-loong-bot-project\module\petpeter\__init__.py", line 30, in <module>
    BOT = bot()
          └ <class 'library.Bot.bot'>

  File "C:\Users\Administrator\Desktop\god-loong-bot-project\library\Bot.py", line 6, in __init__
    self.weijingci = json.loads(f.read())
    │                │    │     │ └ <method 'read' of '_io.TextIOWrapper' objects>
    │                │    │     └ <_io.TextIOWrapper name='C:\\Users\\Administrator\\Desktop\\god-loong-bot-project/library/weijinci.txt' mode='r' encoding='cp...
    │                │    └ <function loads at 0x00000205ADC8A8C0>
    │                └ <module 'json' from 'D:\\Python310\\lib\\json\\__init__.py'>
    └ <library.Bot.bot object at 0x00000205DF7BE3E0>

UnicodeDecodeError: 'gbk' codec can't decode byte 0x9c in position 10: illegal multibyte sequence


During handling of the above exception, another exception occurred:


Traceback (most recent call last):

> File "C:\Users\Administrator\Desktop\god-loong-bot-project\main.py", line 33, in <module>
    modules.require_modules(saya, log_exception=False)
    │       │               └ <graia.saya.Saya object at 0x00000205AEC8A5F0>
    │       └ <function Modules.require_modules at 0x00000205AFFE48B0>
    └ Modules(12)
      Module(中心服务)
      	pack: module.hub_service
      	version: 0.1b
      	author: ['nullqwertyuiop']
      	pypi: False
      	category: utility...

  File "C:\Users\Administrator\Desktop\god-loong-bot-project\module\__init__.py", line 71, in require_modules
    self.require_module(module, saya, log_exception)
    │    │              │       │     └ False
    │    │              │       └ <graia.saya.Saya object at 0x00000205AEC8A5F0>
    │    │              └ Module(petpeter)
    │    │                	pack: module.petpeter
    │    │                	version: Unknown
    │    │                	author: ['Unknown']
    │    │                	pypi: False
    │    │                	category: miscellaneous
    │    │                	descrip...
    │    └ <function Modules.require_module at 0x00000205AFFE4940>
    └ Modules(12)
      Module(中心服务)
      	pack: module.hub_service
      	version: 0.1b
      	author: ['nullqwertyuiop']
      	pypi: False
      	category: utility...

  File "C:\Users\Administrator\Desktop\god-loong-bot-project\module\__init__.py", line 99, in require_module
    logger.error(e)
    └ <module 'module.logger' from 'C:\\Users\\Administrator\\Desktop\\god-loong-bot-project\\module\\logger\\__init__.py'>

AttributeError: module 'module.logger' has no attribute 'error'
2022-08-13 14:34:17.654 | ERROR    | module:require_module:99 - HubService 未启用
2022-08-13 14:34:17.659 | INFO     | graia.saya:require:134 - module loading finished: module.Nudge
2022-08-13 14:34:17.948 | INFO     | graia.saya:require:134 - module loading finished: module.anyvoice
2022-08-13 14:34:17.967 | INFO     | graia.saya:require:134 - module loading finished: module.groupmanager
2022-08-13 14:34:18.130 | ERROR    | module:require_module:99 - 'gbk' codec can't decode byte 0x9c in position 10: illegal multibyte sequence
2022-08-13 14:34:18.135 | INFO     | graia.saya:require:134 - module loading finished: module.logger
2022-08-13 14:34:18.149 | INFO     | graia.saya:require:134 - module loading finished: module.manager
2022-08-13 14:34:18.152 | ERROR    | graia.ariadne.util:loguru_exc_callback:101 - Exception:
Traceback (most recent call last):

  File "C:\Users\Administrator\Desktop\god-loong-bot-project\module\__init__.py", line 87, in require_module
    saya.require(module.pack)
    │    │       │      └ 'module.petpeter'
    │    │       └ Module(petpeter)
    │    │         	pack: module.petpeter
    │    │         	version: Unknown
    │    │         	author: ['Unknown']
    │    │         	pypi: False
    │    │         	category: miscellaneous
    │    │         	descrip...
    │    └ <function Saya.require at 0x000001D5FF9EC550>
    └ <graia.saya.Saya object at 0x000001D58190A620>

  File "C:\Users\Administrator\Desktop\god-loong-bot-project\.venv\lib\site-packages\graia\saya\__init__.py", line 120, in require
    channel = self.require_resolve(module)
              │    │               └ 'module.petpeter'
              │    └ <function Saya.require_resolve at 0x000001D5FF9EC430>
              └ <graia.saya.Saya object at 0x000001D58190A620>

  File "C:\Users\Administrator\Desktop\god-loong-bot-project\.venv\lib\site-packages\graia\saya\__init__.py", line 76, in require_resolve
    imported_module = importlib.import_module(module, module)
                      │         │             │       └ 'module.petpeter'
                      │         │             └ 'module.petpeter'
                      │         └ <function import_module at 0x000001D5FE754280>
                      └ <module 'importlib' from 'D:\\Python310\\lib\\importlib\\__init__.py'>

  File "D:\Python310\lib\importlib\__init__.py", line 126, in import_module
    return _bootstrap._gcd_import(name[level:], package, level)
           │          │           │    │        │        └ 0
           │          │           │    │        └ 'module.petpeter'
           │          │           │    └ 0
           │          │           └ 'module.petpeter'
           │          └ <function _gcd_import at 0x000001D5FE0F3490>
           └ <module '_frozen_importlib' (frozen)>

  File "<frozen importlib._bootstrap>", line 1050, in _gcd_import
  File "<frozen importlib._bootstrap>", line 1027, in _find_and_load
  File "<frozen importlib._bootstrap>", line 1006, in _find_and_load_unlocked
  File "<frozen importlib._bootstrap>", line 688, in _load_unlocked
  File "<frozen importlib._bootstrap_external>", line 883, in exec_module
  File "<frozen importlib._bootstrap>", line 241, in _call_with_frames_removed

  File "C:\Users\Administrator\Desktop\god-loong-bot-project\module\petpeter\__init__.py", line 30, in <module>
    BOT = bot()
          └ <class 'library.Bot.bot'>

  File "C:\Users\Administrator\Desktop\god-loong-bot-project\library\Bot.py", line 6, in __init__
    self.weijingci = json.loads(f.read())
    │                │    │     │ └ <method 'read' of '_io.TextIOWrapper' objects>
    │                │    │     └ <_io.TextIOWrapper name='C:\\Users\\Administrator\\Desktop\\god-loong-bot-project/library/weijinci.txt' mode='r' encoding='cp...
    │                │    └ <function loads at 0x000001D5FF4FA8C0>
    │                └ <module 'json' from 'D:\\Python310\\lib\\json\\__init__.py'>
    └ <library.Bot.bot object at 0x000001D5B146E410>

UnicodeDecodeError: 'gbk' codec can't decode byte 0x9c in position 10: illegal multibyte sequence


During handling of the above exception, another exception occurred:


Traceback (most recent call last):

> File "C:\Users\Administrator\Desktop\god-loong-bot-project\main.py", line 33, in <module>
    modules.require_modules(saya, log_exception=False)
    │       │               └ <graia.saya.Saya object at 0x000001D58190A620>
    │       └ <function Modules.require_modules at 0x000001D582C648B0>
    └ Modules(12)
      Module(中心服务)
      	pack: module.hub_service
      	version: 0.1b
      	author: ['nullqwertyuiop']
      	pypi: False
      	category: utility...

  File "C:\Users\Administrator\Desktop\god-loong-bot-project\module\__init__.py", line 71, in require_modules
    self.require_module(module, saya, log_exception)
    │    │              │       │     └ False
    │    │              │       └ <graia.saya.Saya object at 0x000001D58190A620>
    │    │              └ Module(petpeter)
    │    │                	pack: module.petpeter
    │    │                	version: Unknown
    │    │                	author: ['Unknown']
    │    │                	pypi: False
    │    │                	category: miscellaneous
    │    │                	descrip...
    │    └ <function Modules.require_module at 0x000001D582C64940>
    └ Modules(12)
      Module(中心服务)
      	pack: module.hub_service
      	version: 0.1b
      	author: ['nullqwertyuiop']
      	pypi: False
      	category: utility...

  File "C:\Users\Administrator\Desktop\god-loong-bot-project\module\__init__.py", line 99, in require_module
    logger.error(e)
    └ <module 'module.logger' from 'C:\\Users\\Administrator\\Desktop\\god-loong-bot-project\\module\\logger\\__init__.py'>

AttributeError: module 'module.logger' has no attribute 'error'
2022-08-13 14:35:34.083 | ERROR    | module:require_module:99 - HubService 未启用
2022-08-13 14:35:34.091 | INFO     | graia.saya:require:134 - module loading finished: module.Nudge
2022-08-13 14:35:34.392 | INFO     | graia.saya:require:134 - module loading finished: module.anyvoice
2022-08-13 14:35:34.415 | INFO     | graia.saya:require:134 - module loading finished: module.groupmanager
2022-08-13 14:35:34.595 | INFO     | graia.saya:require:134 - module loading finished: module.lofter
2022-08-13 14:35:34.603 | INFO     | graia.saya:require:134 - module loading finished: module.logger
2022-08-13 14:35:34.621 | INFO     | graia.saya:require:134 - module loading finished: module.manager
2022-08-13 14:35:34.639 | INFO     | graia.saya:require:134 - module loading finished: module.petpeter
2022-08-13 14:35:34.793 | INFO     | graia.saya:require:134 - module loading finished: module.ping
2022-08-13 14:35:34.805 | INFO     | graia.saya:require:134 - module loading finished: module.signin
2022-08-13 14:35:34.815 | INFO     | graia.saya:require:134 - module loading finished: module.song
2022-08-13 14:35:34.913 | INFO     | graia.saya:require:134 - module loading finished: module.system
2022-08-13 14:35:34.916 | INFO     | launart.manager:launch_blocking:446 - Starting launart main task...
2022-08-13 14:35:34.919 | INFO     | launart.manager:launch:319 - Launching 5 components as async task...
2022-08-13 14:35:35.013 | INFO     | graia.ariadne.service:base_telemetry:106 - 
    _         _           _
   / \   _ __(_) __ _  __| |_ __   ___
  / _ \ | '__| |/ _` |/ _` | '_ \ / _ \
 / ___ \| |  | | (_| | (_| | | | |  __/
/_/   \_\_|  |_|\__,_|\__,_|_| |_|\___|

graiax-silkcoder: 0.3.2
graia-amnesia: 0.5.8
graia-ariadne: 0.8.2
graia-broadcast: 0.18.2
graia-saya: 0.0.16
graia-scheduler: 0.0.8
launart: 0.6.0
statv: 0.3.2
2022-08-13 14:35:35.027 | INFO     | launart.manager:_launchable_task_done_callback:59 - [elizabeth.connection.1804385478.http_client_connection] completed.
2022-08-13 14:35:35.032 | SUCCESS  | launart.manager:launch:358 - Layer #1:[cache.client, http.universal_client] preparation completed.
2022-08-13 14:35:35.037 | SUCCESS  | launart.manager:launch:358 - Layer #3:[elizabeth.service] preparation completed.
2022-08-13 14:35:35.039 | INFO     | launart.manager:launch:363 - All components prepared, start blocking phase.
2022-08-13 14:35:36.468 | SUCCESS  | graia.ariadne.connection.ws:_:69 - Successfully got session key
2022-08-13 14:35:47.082 | INFO     | graia.ariadne.model:log:84 - 1804385478: [RECV][<$ǿĀC>real的泡面桶<$ǿĀC>(1014391660)] ღ小鹿᭄ꦿ࿐(1712339881) -> [语音]
2022-08-13 14:35:47.986 | INFO     | graia.ariadne.model:log:84 - 1804385478: [RECV][<$ǿĀC>real的泡面桶<$ǿĀC>(1014391660)] 你，(2570151270) -> 严阵以待
2022-08-13 14:35:49.010 | INFO     | graia.ariadne.model:log:84 - 1804385478: [RECV][✨天狼星炎的破烂道观✨(864112687)] 韵律动天乾坤易(2179830598) -> 呃
2022-08-13 14:35:50.680 | INFO     | graia.ariadne.model:log:84 - 1804385478: [RECV][无人经营的茶坊(372226771)] 海洋的创造者(1732066149) -> [图片]
2022-08-13 14:35:53.268 | INFO     | graia.ariadne.model:log:84 - 1804385478: [RECV][<$ǿĀC>real的泡面桶<$ǿĀC>(1014391660)] Fu_Sheng15🐾(1701269483) -> @3240345610 泰坦陨落
2022-08-13 14:35:54.597 | INFO     | graia.ariadne.model:log:84 - 1804385478: [RECV][无人经营的茶坊(372226771)] 海洋的创造者(1732066149) -> [图片]
2022-08-13 14:35:56.688 | INFO     | graia.ariadne.model:log:84 - 1804385478: [RECV][<$ǿĀC>real的泡面桶<$ǿĀC>(1014391660)] Fu_Sheng15🐾(1701269483) -> 深海迷航
2022-08-13 14:35:59.002 | INFO     | graia.ariadne.model:log:84 - 1804385478: [RECV][Furry Developers Home(275720357)] 灾飞的以太龙(2970290021) -> 坏了
2022-08-13 14:35:59.847 | INFO     | graia.ariadne.model:log:84 - 1804385478: [RECV][无人经营的茶坊(372226771)] 海洋的创造者(1732066149) -> [图片]
2022-08-13 14:36:03.255 | INFO     | graia.ariadne.model:log:84 - 1804385478: [RECV][无人经营的茶坊(372226771)] 海洋的创造者(1732066149) -> 雪王牛逼
2022-08-13 14:36:03.562 | INFO     | graia.ariadne.model:log:84 - 1804385478: [RECV][无人经营的茶坊(372226771)] 天空的缔造者(750913326) -> 揉揉耳朵
2022-08-13 14:36:05.677 | INFO     | graia.ariadne.model:log:84 - 1804385478: [RECV][✨天狼星炎的破烂道观✨(864112687)] 韵律动天乾坤易(2179830598) -> 撑衣杆
